Workbook

Sheet 요약
A1: NETS(ACOM) 라벨저울 – 스페인어권 비유럽 수입상/유통사 리스트
A2: 조사일: 2026-10-08 · 웹 검색 결과 기반 (업체 사이트 직접 접속 불가) – 연락 전 반드시 최신 연락처 재확인
A4: 우선순위 기준
A5: A | B5: 1차 컨택 – 라벨저울 판매 중 + 멀티브랜드/전환 가능
A6: B | B6: 2차 – 관련 채널이나 브랜드 묶임·정보 부족
A7: C | B7: 참고 – 서비스업체, 경쟁사 전속, 미검증
A9: 국가별 집계
A10: 국가 | B10: 전체 | C10: A | D10: B | E10: C | F10: 이메일 보유
A11: 멕시코 | B11: =COUNTIF('바이어 리스트'!$C$2:$C$106,A11) -> 12 | C11: =COUNTIFS('바이어 리스트'!$C$2:$C$106,$A11,'바이어 리스트'!$B$2:$B$106,"A") -> 3 | D11: =COUNTIFS('바이어 리스트'!$C$2:$C$106,$A11,'바이어 리스트'!$B$2:$B$106,"B") -> 5 | E11: =COUNTIFS('바이어 리스트'!$C$2:$C$106,$A11,'바이어 리스트'!$B$2:$B$106,"C") -> 4 | F11: =COUNTIFS('바이어 리스트'!$C$2:$C$106,A11,'바이어 리스트'!$G$2:$G$106,"*@*") -> 12
A12: 과테말라 | B12: =COUNTIF('바이어 리스트'!$C$2:$C$106,A12) -> 5 | C12: =COUNTIFS('바이어 리스트'!$C$2:$C$106,$A12,'바이어 리스트'!$B$2:$B$106,"A") -> 1 | D12: =COUNTIFS('바이어 리스트'!$C$2:$C$106,$A12,'바이어 리스트'!$B$2:$B$106,"B") -> 3 | E12: =COUNTIFS('바이어 리스트'!$C$2:$C$106,$A12,'바이어 리스트'!$B$2:$B$106,"C") -> 1 | F12: =COUNTIFS('바이어 리스트'!$C$2:$C$106,A12,'바이어 리스트'!$G$2:$G$106,"*@*") -> 5
A13: 엘살바도르 | B13: =COUNTIF('바이어 리스트'!$C$2:$C$106,A13) -> 3 | C13: =COUNTIFS('바이어 리스트'!$C$2:$C$106,$A13,'바이어 리스트'!$B$2:$B$106,"A") -> 1 | D13: =COUNTIFS('바이어 리스트'!$C$2:$C$106,$A13,'바이어 리스트'!$B$2:$B$106,"B") -> 2 | E13: =COUNTIFS('바이어 리스트'!$C$2:$C$106,$A13,'바이어 리스트'!$B$2:$B$106,"C") -> 0 | F13: =COUNTIFS('바이어 리스트'!$C$2:$C$106,A13,'바이어 리스트'!$G$2:$G$106,"*@*") -> 3
A14: 온두라스 | B14: =COUNTIF('바이어 리스트'!$C$2:$C$106,A14) -> 6 | C14: =COUNTIFS('바이어 리스트'!$C$2:$C$106,$A14,'바이어 리스트'!$B$2:$B$106,"A") -> 2 | D14: =COUNTIFS('바이어 리스트'!$C$2:$C$106,$A14,'바이어 리스트'!$B$2:$B$106,"B") -> 2 | E14: =COUNTIFS('바이어 리스트'!$C$2:$C$106,$A14,'바이어 리스트'!$B$2:$B$106,"C") -> 2 | F14: =COUNTIFS('바이어 리스트'!$C$2:$C$106,A14,'바이어 리스트'!$G$2:$G$106,"*@*") -> 5
A15: 니카라과 | B15: =COUNTIF('바이어 리스트'!$C$2:$C$106,A15) -> 3 | C15: =COUNTIFS('바이어 리스트'!$C$2:$C$106,$A15,'바이어 리스트'!$B$2:$B$106,"A") -> 1 | D15: =COUNTIFS('바이어 리스트'!$C$2:$C$106,$A15,'바이어 리스트'!$B$2:$B$106,"B") -> 1 | E15: =COUNTIFS('바이어 리스트'!$C$2:$C$106,$A15,'바이어 리스트'!$B$2:$B$106,"C") -> 1 | F15: =COUNTIFS('바이어 리스트'!$C$2:$C$106,A15,'바이어 리스트'!$G$2:$G$106,"*@*") -> 3
A16: 코스타리카 | B16: =COUNTIF('바이어 리스트'!$C$2:$C$106,A16) -> 5 | C16: =COUNTIFS('바이어 리스트'!$C$2:$C$106,$A16,'바이어 리스트'!$B$2:$B$106,"A") -> 2 | D16: =COUNTIFS('바이어 리스트'!$C$2:$C$106,$A16,'바이어 리스트'!$B$2:$B$106,"B") -> 2 | E16: =COUNTIFS('바이어 리스트'!$C$2:$C$106,$A16,'바이어 리스트'!$B$2:$B$106,"C") -> 1 | F16: =COUNTIFS('바이어 리스트'!$C$2:$C$106,A16,'바이어 리스트'!$G$2:$G$106,"*@*") -> 4
A17: 파나마 | B17: =COUNTIF('바이어 리스트'!$C$2:$C$106,A17) -> 5 | C17: =COUNTIFS('바이어 리스트'!$C$2:$C$106,$A17,'바이어 리스트'!$B$2:$B$106,"A") -> 1 | D17: =COUNTIFS('바이어 리스트'!$C$2:$C$106,$A17,'바이어 리스트'!$B$2:$B$106,"B") -> 2 | E17: =COUNTIFS('바이어 리스트'!$C$2:$C$106,$A17,'바이어 리스트'!$B$2:$B$106,"C") -> 2 | F17: =COUNTIFS('바이어 리스트'!$C$2:$C$106,A17,'바이어 리스트'!$G$2:$G$106,"*@*") -> 5
A18: 콜롬비아 | B18: =COUNTIF('바이어 리스트'!$C$2:$C$106,A18) -> 8 | C18: =COUNTIFS('바이어 리스트'!$C$2:$C$106,$A18,'바이어 리스트'!$B$2:$B$106,"A") -> 2 | D18: =COUNTIFS('바이어 리스트'!$C$2:$C$106,$A18,'바이어 리스트'!$B$2:$B$106,"B") -> 5 | E18: =COUNTIFS('바이어 리스트'!$C$2:$C$106,$A18,'바이어 리스트'!$B$2:$B$106,"C") -> 1 | F18: =COUNTIFS('바이어 리스트'!$C$2:$C$106,A18,'바이어 리스트'!$G$2:$G$106,"*@*") -> 7
A19: 에콰도르 | B19: =COUNTIF('바이어 리스트'!$C$2:$C$106,A19) -> 6 | C19: =COUNTIFS('바이어 리스트'!$C$2:$C$106,$A19,'바이어 리스트'!$B$2:$B$106,"A") -> 1 | D19: =COUNTIFS('바이어 리스트'!$C$2:$C$106,$A19,'바이어 리스트'!$B$2:$B$106,"B") -> 2 | E19: =COUNTIFS('바이어 리스트'!$C$2:$C$106,$A19,'바이어 리스트'!$B$2:$B$106,"C") -> 3 | F19: =COUNTIFS('바이어 리스트'!$C$2:$C$106,A19,'바이어 리스트'!$G$2:$G$106,"*@*") -> 6
A20: 도미니카공화국 | B20: =COUNTIF('바이어 리스트'!$C$2:$C$106,A20) -> 4 | C20: =COUNTIFS('바이어 리스트'!$C$2:$C$106,$A20,'바이어 리스트'!$B$2:$B$106,"A") -> 1 | D20: =COUNTIFS('바이어 리스트'!$C$2:$C$106,$A20,'바이어 리스트'!$B$2:$B$106,"B") -> 3 | E20: =COUNTIFS('바이어 리스트'!$C$2:$C$106,$A20,'바이어 리스트'!$B$2:$B$106,"C") -> 0 | F20: =COUNTIFS('바이어 리스트'!$C$2:$C$106,A20,'바이어 리스트'!$G$2:$G$106,"*@*") -> 4
A21: 베네수엘라 | B21: =COUNTIF('바이어 리스트'!$C$2:$C$106,A21) -> 6 | C21: =COUNTIFS('바이어 리스트'!$C$2:$C$106,$A21,'바이어 리스트'!$B$2:$B$106,"A") -> 0 | D21: =COUNTIFS('바이어 리스트'!$C$2:$C$106,$A21,'바이어 리스트'!$B$2:$B$106,"B") -> 5 | E21: =COUNTIFS('바이어 리스트'!$C$2:$C$106,$A21,'바이어 리스트'!$B$2:$B$106,"C") -> 1 | F21: =COUNTIFS('바이어 리스트'!$C$2:$C$106,A21,'바이어 리스트'!$G$2:$G$106,"*@*") -> 6
A22: 푸에르토리코 | B22: =COUNTIF('바이어 리스트'!$C$2:$C$106,A22) -> 3 | C22: =COUNTIFS('바이어 리스트'!$C$2:$C$106,$A22,'바이어 리스트'!$B$2:$B$106,"A") -> 0 | D22: =COUNTIFS('바이어 리스트'!$C$2:$C$106,$A22,'바이어 리스트'!$B$2:$B$106,"B") -> 1 | E22: =COUNTIFS('바이어 리스트'!$C$2:$C$106,$A22,'바이어 리스트'!$B$2:$B$106,"C") -> 2 | F22: =COUNTIFS('바이어 리스트'!$C$2:$C$106,A22,'바이어 리스트'!$G$2:$G$106,"*@*") -> 3
... A28: 파라과이 | B28: =COUNTIF('바이어 리스트'!$C$2:$C$106,A28) -> 4 | C28: =COUNTIFS('바이어 리스트'!$C$2:$C$106,$A28,'바이어 리스트'!$B$2:$B$106,"A") -> 2 | D28: =COUNTIFS('바이어 리스트'!$C$2:$C$106,$A28,'바이어 리스트'!$B$2:$B$106,"B") -> 0 | E28: =COUNTIFS('바이어 리스트'!$C$2:$C$106,$A28,'바이어 리스트'!$B$2:$B$106,"C") -> 2 | F28: =COUNTIFS('바이어 리스트'!$C$2:$C$106,A28,'바이어 리스트'!$G$2:$G$106,"*@*") -> 4
A29: 합계 | B29: =SUM(B11:B28) -> 105 | C29: =SUM(C11:C28) -> 28 | D29: =SUM(D11:D28) -> 46 | E29: =SUM(E11:E28) -> 31 | F29: =SUM(F11:F28) -> 101
A31: 메일 발송: '메일 발송용' 시트(이메일 1개당 1행, 메일머지용). 영업 진행 기록: '바이어 리스트' 시트 오른쪽 노란색 열(컨택일/상태/담당자/메모)에 직접 입력하세요. 상태는 드롭다운 선택.

Sheet 메일 발송용
A1: 우선순위 | B1: 국가 | C1: 회사명 | D1: 이메일 | E1: 대표 주소 여부
A2: A | B2: 과테말라 | C2: Inter-Americana | D2: ventas@inter-americana.com | E2: 대표
A3: A | B3: 니카라과 | C3: Azocar Nicaragua | D3: info@azocarnicaragua.com | E3: 대표
A4: A | B4: 도미니카공화국 | C4: Serpoca | D4: ventas@serpoca.com.do | E4: 대표
A5: A | B5: 도미니카공화국 | C5: Serpoca | D5: info@serpoca.com.do
A6: A | B6: 멕시코 | C6: Noscom | D6: contacto@noscom.mx | E6: 대표
A7: A | B7: 멕시코 | C7: Básculas Mexicanas S.A. de C.V. (Básculas IBN) | D7: ventas@basculasibn.com | E7: 대표
A8: A | B8: 멕시코 | C8: Rhino Maquinaria S.A. de C.V. | D8: info@rhino.mx | E8: 대표
A9: A | B9: 볼리비아 | C9: CAS – Computer & Sensors SRL | D9: info@cas-bo.com | E9: 대표
A10: A | B10: 볼리비아 | C10: CAS – Computer & Sensors SRL | D10: ventas@cas-bo.com
A11: A | B11: 볼리비아 | C11: Exim SRL | D11: info@exim.com.bo | E11: 대표
A12: A | B12: 아르헨티나 | C12: Grupo Hasar (Hasar Sistemas SRL) | D12: info@hasar.com | E12: 대표
A13: A | B13: 에콰도르 | C13: La Competencia S.A. | D13: ventas@competencia.com.ec | E13: 대표
A14: A | B14: 에콰도르 | C14: La Competencia S.A. | D14: marketing@competencia.com.ec
A15: A | B15: 엘살바도르 | C15: Puntos de Venta El Salvador | D15: info@puntosdeventa.com.sv | E15: 대표
A16: A | B16: 온두라스 | C16: IMERCO Honduras | D16: ventas@imercohn.net | E16: 대표
A17: A | B17: 온두라스 | C17: Inter-Americana Honduras | D17: ventashn@inter-americana.com | E17: 대표
A18: A | B18: 우루과이 | C18: Baudin Equipamientos | D18: ventas@baudinequipamientos.com | E18: 대표
A19: A | B19: 우루과이 | C19: Baudin Equipamientos | D19: gerencia@baudinequipamientos.com
A20: A | B20: 우루과이 | C20: Ser-Tec | D20: ventas@ser-tec.com.uy | E20: 대표
A21: A | B21: 우루과이 | C21: Ser-Tec | D21: info@ser-tec.com.uy
A22: A | B22: 칠레 | C22: Tecno Rebas | D22: ventas@tecnorebas.cl | E22: 대표
A23: A | B23: 칠레 | C23: Ing Métrica SpA | D23: contacto@ingmetrica.cl | E23: 대표
A24: A | B24: 칠레 | C24: Balanzas.cl | D24: contacto@balanzas.cl | E24: 대표
A25: A | B25: 코스타리카 | C25: Nexius | D25: eguerrero@nexius.tools | E25: 대표
A26: A | B26: 코스타리카 | C26: Nexius | D26: melramos@nexius.tools
A27: A | B27: 코스타리카 | C27: Romanas Azocar | D27: info@azocarcr.com | E27: 대표
A28: A | B28: 콜롬비아 | C28: BBG Colombia SAS (Básculas y Balanzas Guadalupe) | D28: ventas@basculasbbg.com | E28: 대표
A29: A | B29: 콜롬비아 | C29: BBG Colombia SAS (Básculas y Balanzas Guadalupe) | D29: distribuidoresmedellin@basculasbbg.com
A30: A | B30: 콜롬비아 | C30: BBG Colombia SAS (Básculas y Balanzas Guadalupe) | D30: medellin@basculasbbg.com
A31: A | B31: 콜롬비아 | C31: BBG Colombia SAS (Básculas y Balanzas Guadalupe) | D31: info@basculasbbg.com
A32: A | B32: 콜롬비아 | C32: Badecol (Balanzas de Colombia) | D32: ventas@badecol.com | E32: 대표
A33: A | B33: 콜롬비아 | C33: Badecol (Balanzas de Colombia) | D33: comercial@badecol.com
A34: A | B34: 콜롬비아 | C34: Badecol (Balanzas de Colombia) | D34: exportaciones@badecol.com
A35: A | B35: 파나마 | C35: STH Panamá | D35: ventas@sthpanama.com | E35: 대표
A36: A | B36: 파라과이 | C36: Balanzas Paraguayas S.A. (Balpar) | D36: licitaciones@balpar.com.py | E36: 대표
A37: A | B37: 파라과이 | C37: HPTI Sistemas y Equipamientos | D37: licitaciones@hpti.com.py | E37: 대표
A38: A | B38: 페루 | C38: Gufra Perú | D38: ventas@gufraperu.com | E38: 대표
A39: A | B39: 페루 | C39: Gufra Perú | D39: administracion@gufraperu.com
A40: A | B40: 페루 | C40: Invercorp Perú | D40: ventas@invercorp-peru.com | E40: 대표
...

Sheet 바이어 리스트
A1: No | B1: 우선순위 | C1: 국가 | D1: 회사명 | E1: 도시 | F1: 웹사이트 | G1: 이메일 | H1: 전화/WhatsApp | I1: 이메일 출처 | J1: 연락 메모 | K1: 취급 브랜드/제품 | L1: 유형 | M1: NETS 적합도 | N1: 적합 사유 | O1: 출처 URL | P1: 컨택일 | Q1: 상태 | R1: 담당자 | S1: 메모
A2: 1 | B2: A | C2: 멕시코 | D2: Noscom | E2: Tijuana / CDMX | F2: noscom.mx | G2: contacto@noscom.mx | H2: Tijuana (664) 647-5632; CDMX (55) 5208-8565; WA 663 208 8849 | I2: 기존 조사 (회사 사이트/디렉토리) | K2: SAM4s POS + CAS 라벨저울(CN1, CL5200/5500) | L2: 유통(POS+저울) | M2: 상 | N2: POS+라벨저울 번들 영업, 이미 한국 브랜드(CAS) 취급 → 한국산 대안 제안 용이 | O2: https://www.noscom.mx/
A3: 2 | B3: A | C3: 멕시코 | D3: Básculas Mexicanas S.A. de C.V. (Básculas IBN) | E3: Monterrey, NL | F3: basculasibn.com | G3: ventas@basculasibn.com | H3: +52 81 8129 6799 / 8129 6788; WA 81 8163 3310 | I3: 기존 조사 (회사 사이트/디렉토리) | K3: 슈퍼마켓용 라벨저울(자체 e-tikket), DIGI, 포션저울 | L3: 수입/딜러 | M3: 상 | N3: 슈퍼용 라벨저울 판매, 멀티브랜드, 한국 브랜드 없음 | O3: https://basculasibn.com/basculas-etiquetadoras/
A4: 3 | B4: A | C4: 멕시코 | D4: Rhino Maquinaria S.A. de C.V. | E4: Atizapán, Edo. Méx. | F4: rhino.mx | G4: info@rhino.mx | H4: (55) 4429 0229; 800 377 8242 | I4: 기존 조사 (회사 사이트/디렉토리) | K4: 자체 브랜드 Rhino(수입 OEM), BAET-30 라벨저울, 전국 서비스망 | L4: 브랜드 수입사 | M4: 중상 | N4: 아시아산 OEM 자체브랜드 운영 → NETS OEM/ODM 파트너 가능(동시에 경쟁사) | O4: https://www.rhino.mx/producto/bascula-etiquetadora-baet-30/
A5: 4 | B5: B | C5: 멕시코 | D5: Microdatanorte / MR Tienda | E5: Baja California, BCS | F5: microdatanorte.com.mx | G5: ventas@microdatanorte.com.mx | H5: 615 157 1230; WA 615 155 8228 | I5: 기존 조사 (회사 사이트/디렉토리) | K5: POS SW/HW + CAS 저울(CL5000/5500) | L5: POS 딜러 | M5: 중상 | N5: CAS 라벨저울 파는 POS 통합업체, 지역 한정 | O5: http://www.microdatanorte.com.mx/basculas/
A6: 5 | B6: B | C6: 멕시코 | D6: Grupo Mexba | E6: Estado de México (전국 서비스) | F6: mexba.com.mx | G6: ventas@mexba.com.mx; gmexba@gmail.com | I6: 기존 조사 (회사 사이트/디렉토리) | K6: DIGI 멕시코 독점 유통 표방(SM-120, SM-100H), 32개 주 서비스 | L6: 독점유통+서비스 | M6: 중 | N6: 소매저울 채널 강력하나 DIGI 묶임 → 세컨드/가격대 브랜드로 제안 | O6: https://mexba.com.mx/index.php
A7: 6 | B7: B | C7: 멕시코 | D7: Asesoría Integral de Básculas (AIBSA) | E7: Puebla | F7: aibasculas.com | G7: areacomercial@aibasculas.com | H7: (222) 220 3051 / 220 0267 / 213 1159 | I7: 기존 조사 (회사 사이트/디렉토리) | K7: CAS 등 판매·서비스 | L7: 딜러/서비스 | M7: 중 | N7: CAS 경험, 지역 업체 | O7: https://www.aibasculas.com/
A8: 7 | B8: B | C8: 멕시코 | D8: Sistemas Digitales MX | E8: Baja California | F8: sistemas-digitales-mx.com | G8: german.reyn@sistemas-digitales-mx.com | H8: 664 238 7690; 664 103 7186 | I8: sistemas-digitales-mx.com (메타데이터, 신뢰도 낮음) | K8: CAS CL-5200, CN1 + CL-Works | L8: 딜러 | M8: 중 | N8: 소규모 CAS 리셀러 | O8: https://sistemas-digitales-mx.com/bascula-electronica-digital-etiquetadora-cas-cl-5200/
A9: 8 | B9: B | C9: 멕시코 | D9: Básculas Internacionales de México (BIM) | E9: Tijuana, BC | G9: ventas.tij@basculasint.com | H9: 664 120 5997; (디렉토리) | I9: 기존 조사 (회사 사이트/디렉토리) | K9: 저울 전반, 전국 대리점망 | L9: 유통 | M9: 중 | N9: 전국 딜러망 (디렉토리 정보, 오래됐을 수 있음) | O9: https://construex.com.mx/exhibidores/basculas_internacionales_de_mexico_bim
A10: 9 | B10: C | C10: 멕시코 | D10: Cereco / Equipos Torrey | E10: CDMX, Puebla | F10: equipostorrey.com.mx | G10: info@cereco.com.mx | H10: 55-2898-3775; WA 55-2724-1542 | I10: 기존 조사 (회사 사이트/디렉토리) | K10: Torrey 라벨저울(W-Label), 주방설비 | L10: 딜러 | M10: 중하 | N10: Torrey 충성 딜러, 정육점·델리 판매 | O10: https://equipostorrey.com.mx/categoria-producto/pesaje/basculas-etiquetadoras/
A11: 10 | B11: C | C11: 멕시코 | D11: JL Rodríguez S.A. de C.V. | E11: Guadalajara | F11: jlrodriguez.com.mx | G11: contacto@jlrodriguez.com.mx; JLRODRIGUEZTR@gmail.com | H11: 33-3811-8047 / 8981 / 5348 | I11: jlrodriguez.com.mx/contacto; construex | J11: WA +52 33 2236 2702 | K11: Torrey 저울, 냉장설비 | L11: 딜러 | M11: 중하 | N11: Torrey 딜러 | O11: http://www.jlrodriguez.com.mx/productos-y-servicios
A12: 11 | B12: C | C12: 멕시코 | D12: Badimex | E12: Querétaro / CDMX | F12: badimex.mx | G12: info@badimex.mx | H12: (44) 2100-4813; WA (55) 6785-6352 | I12: 기존 조사 (회사 사이트/디렉토리) | K12: 디지털 저울, 업소용 기계 | L12: 딜러/소매 | M12: 중하 | N12: 라벨저울 취급 미확인 | O12: https://www.badimex.mx/
A13: 12 | B13: A | C13: 과테말라 | D13: Inter-Americana | E13: Guatemala City 외 (온두라스 지사) | F13: inter-americana.com | G13: ventas@inter-americana.com | H13: PBX (502) 2427-5000 | I13: 기존 조사 (회사 사이트/디렉토리) | K13: Torrey 라벨저울, 식품가공·정육 장비 | L13: 수입/유통 | M13: 상 | N13: GT+HN 정육·식품 소매에 라벨저울 판매, Torrey만 취급 | O13: https://www.inter-americana.com/pesaje
A14: 13 | B14: B | C14: 과테말라 | D14: Soluciones Exactas S.A. | E14: Guatemala (중미 커버) | F14: soluciones-exactas.com | G14: krosales@soluciones-exactas.com | H14: (502) 5968-5590; 2460-8068 | I14: 기존 조사 (회사 사이트/디렉토리) | K14: 멀티브랜드 산업/정밀/상업용 저울, 교정 | L14: 유통+서비스 | M14: 중상 | N14: 멀티브랜드 수입 + 교정 역량 | O14: https://www.soluciones-exactas.com/
A15: 14 | B15: B | C15: 과테말라 | D15: PKM Industrial S.A. | E15: Guatemala | F15: pkm-gua.com | G15: administracion@pkm-gua.com | H15: (502) 6633-9972; 2375-2147 | I15: pkm-gua.com | K15: Rice Lake, Dini Argeo, Sartorius | L15: 유통 | M15: 중 | N15: 산업용 중심, 상업용 벤치저울도 판매 | O15: https://www.pkm-gua.com/
A16: 15 | B16: B | C16: 과테말라 | D16: Servitebb | E16: Guatemala City | F16: servitebb.com | G16: servicioespecializado@servitebb.com | H16: WA +502 5039-5386 | I16: 기존 조사 (회사 사이트/디렉토리) | K16: 상업용·플랫폼·트럭 저울, 수리 | L16: 딜러/서비스 | M16: 중 | N16: 소매저울 판매+서비스 | O16: https://www.servitebb.com/
A17: 16 | B17: C | C17: 과테말라 | D17: Probaza S.A. | E17: Guatemala | F17: probazagt.com | G17: servicios@probazagt.com | H17: 2292-5397 | I17: 기존 조사 (회사 사이트/디렉토리) | K17: 교정/인증 (전 브랜드) | L17: 서비스 | M17: 중하 | N17: 수입사 아님, 서비스 파트너 | O17: https://www.probazagt.com/
A18: 17 | B18: A | C18: 엘살바도르 | D18: Puntos de Venta El Salvador | E18: Santa Tecla | F18: puntosdeventa.com.sv | G18: info@puntosdeventa.com.sv | H18: (503) 2556-6707 | I18: 기존 조사 (회사 사이트/디렉토리) | K18: POS HW(Zebra, Epson, Bixolon), 라벨프린터, 저울 | L18: POS 딜러 | M18: 중상 | N18: 저울 파는 POS 채널, 라벨저울 추가 가능 | O18: https://puntosdeventa.com.sv/
A19: 18 | B19: B | C19: 엘살바도르 | D19: Básculas y Balanzas S.A. de C.V. | E19: San Salvador | F19: basculasybalanzassv.com | G19: info@basculasybalanzassv.com | H19: +503 2521-7100 | I19: 기존 조사 (회사 사이트/디렉토리) | K19: CAS 공인/독점 유통(GT,HN,NI,SV), HAENNI, Rice Lake, 교정 | L19: 독점유통+서비스 | M19: 중 | N19: 중미 북부 CAS 메인 채널 – 묶여있을 수 있으나 전환 타깃 | O19: https://basculasybalanzassv.com/distribuidores-autorizados/
A20: 19 | B20: B | C20: 엘살바도르 | D20: Exactos Equipos | E20: San Salvador, San Miguel | F20: exactosequipos.com | G20: exactosequipos@gmail.com | H20: +503 7968-4778 | I20: facebook.com/exactoselsalvador/ | J20: FB 번호 +503 7740 0083 | K20: Rhino, Vinson(멕시코 브랜드) | L20: 딜러 | M20: 중 | N20: 지점망 보유, 라벨저울 브랜드 없음 | O20: https://exactosequipos.com/contacto
A21: 20 | B21: A | C21: 온두라스 | D21: IMERCO Honduras | E21: San Pedro Sula, Tegucigalpa | F21: imercohn.net | G21: ventas@imercohn.net | H21: PBX 3170-3521 | I21: 기존 조사 (회사 사이트/디렉토리) | K21: Torrey 라벨저울(W-LABEL) | L21: 유통 | M21: 상 | N21: 양대 도시에서 라벨저울 판매, Torrey만 취급 | O21: https://imercohn.net/pesaje/
A22: 21 | B22: A | C22: 온두라스 | D22: Inter-Americana Honduras | E22: San Pedro Sula | F22: inter-americana.com/honduras | G22: ventashn@inter-americana.com | H22: (504) 2508-2558 | I22: 기존 조사 (회사 사이트/디렉토리) | K22: Torrey 저울, 식품설비 | L22: 유통 | M22: 상 | N22: 과테말라 본사와 일괄 제안 | O22: https://www.inter-americana.com/honduras
A23: 22 | B23: B | C23: 온두라스 | D23: IPESAH | E23: San Pedro Sula | F23: ipesah.com | G23: cotizaciones@ipesah.com | H23: +504 2504-2016 | I23: 기존 조사 (회사 사이트/디렉토리) | K23: Rice Lake, Dini Argeo 공인, ISO17025 교정랩 | L23: 유통+서비스 | M23: 중 | N23: 서비스/교정 기반 강함, 소매 라벨저울 약함 | O23: https://ipesah.com/
A24: 23 | B24: C | C24: 온두라스 | D24: BABASE | E24: San Pedro Sula | G24: ventashn@babase.net; administracion@babase.net; servicioalcliente@babasehn.com | H24: 2550-0330 (오래된 디렉토리) | I24: babase.net/Contactenos.html; babasehn.com | J24: +504 2552-5091 / 2550-1636 | K24: 저울 공급·서비스 | L24: 딜러/서비스 | M24: 중하 | N24: 정보 오래됨 | O24: https://www.dehonduras.com/honduras/comercio-e-industria/basculas-y-balanzas.php
A25: 24 | B25: C | C25: 온두라스 | D25: F.A. Dalton S.A. de C.V. | E25: San Pedro Sula | H25: 551-3070 (디렉토리) | J25: 이메일 미공개 – Grupo DISAGRO 소속(Mettler 대리), disagro.com 문의폼 이용 | K25: 저울 판매·서비스·교정 | L25: 딜러/서비스 | M25: 하 | N25: 디렉토리 정보만 | O25: https://www.dehonduras.com/honduras/comercio-e-industria/basculas-y-balanzas.php
A26: 25 | B26: A | C26: 니카라과 | D26: Azocar Nicaragua | E26: Managua | F26: azocarnicaragua.com | G26: info@azocarnicaragua.com | H26: +505 7656-0710 / 2276-0215 | I26: 기존 조사 (회사 사이트/디렉토리) | K26: Hiweigh, Ishida, Kretz, CAS, Ohaus, Rice Lake, Datamax 등 | L26: 수입/유통 | M26: 상 | N26: 멀티브랜드 소매라인, 코스타리카 Azocar 자매사 | O26: https://azocarnicaragua.com/contactanos/
A27: 26 | B27: B | C27: 니카라과 | D27: Servibásculas S.A. | E27: Managua | F27: servibasculas.com | G27: ventas@servibasculas.com | H27: +505 2225-1968 | I27: 기존 조사 (회사 사이트/디렉토리) | K27: 티켓 프린트 저울, 방수저울, 설치·교정 | L27: 유통+서비스 | M27: 중상 | N27: 프린트 저울 이미 판매 | O27: https://www.servibasculas.com/
A28: 27 | B28: C | C28: 니카라과 | D28: Básculas Rodríguez Nicaragua | E28: Managua | F28: bascularodriguez.com | G28: basculas.rodriguez@outlook.com | H28: 2225-2409; 8724-6659 | I28: bascularodriguez.com; Facebook | J28: +505 7706 3501 | K28: 트럭저울, 인디케이터, 교정 | L28: 딜러/서비스 | M28: 하 | N28: 산업용 중심 | O28: https://bascularodriguez.com/
A29: 28 | B29: A | C29: 코스타리카 | D29: Nexius | E29: Costa Rica | F29: nexius.tools | G29: eguerrero@nexius.tools; melramos@nexius.tools | H29: WA +506 8873-5883 | I29: nexius.tools | J29: Esteban Guerrero(운영이사); WA +506 8873 5883; La Unión, Cartago | K29: 슈퍼마켓 장비(358품목): Dibal 라벨저울, 셀프계산대 | L29: 유통(슈퍼 장비) | M29: 상 | N29: 슈퍼마켓 납품, 저울은 여러 라인 중 하나 → 추가 브랜드 수용 가능 | O29: https://nexius.tools/catalogo/supermercados/
A30: 29 | B30: A | C30: 코스타리카 | D30: Romanas Azocar | E30: San José | F30: azocarcr.com | G30: info@azocarcr.com | H30: +506 2222-0000; WA 6224-0518 | I30: 기존 조사 (회사 사이트/디렉토리) | K30: 소매/라벨저울(Dibal), ISO17025 랩 | L30: 유통+교정 | M30: 상 | N30: 라벨저울 판매 + 공인 교정, 니카라과 동시 커버 | O30: https://www.azocarcr.com/product-page/etiquetadoras
A31: 30 | B31: B | C31: 코스타리카 | D31: Romanas HSR | E31: San José | F31: romanashsr.com | J31: 이메일 미공개 – romanashsr.com 문의폼 이용 | K31: Dibal 직수입 유통, Datalogic, 라벨저울 | L31: 수입/유통 | M31: 중 | N31: 라벨저울 전문이나 Dibal 전속 | O31: https://www.romanashsr.com/balanzas-etiquetadoras
A32: 31 | B32: B | C32: 코스타리카 | D32: Reproma | E32: Costa Rica | F32: reproma.com | G32: info@reproma.com | I32: reproma.com/contacto/ | J32: +506 2224-9491 | K32: CAS Corporation 공급사 페이지 보유 | L32: 유통 | M32: 중 | N32: CAS 연계, 상세 미확인 | O32: https://www.reproma.com/proveedor/cas-corporation/
A33: 32 | B33: C | C33: 코스타리카 | D33: Romanas Lacost S.A. | E33: Tibás, San José | G33: info@romanaslacost.com; multiservicioslacost@gmail.com | I33: eca.or.cr (인정기관 기록) | J33: +506 2248-0200 | K33: 판매·수리·교정(ISO17025) | L33: 서비스/딜러 | M33: 중하 | N33: 서비스 파트너 | O33: https://ilac.org/?p=126536
A34: 33 | B34: A | C34: 파나마 | D34: STH Panamá | E34: Panama City | F34: sthpanama.com | G34: ventas@sthpanama.com | H34: 343-5668 | I34: 기존 조사 (회사 사이트/디렉토리) | K34: 3nStar POS, 재정프린터, Aclas LS2X·Kretz 라벨저울 | L34: POS 딜러 | M34: 상 | N34: 중국/아르헨 라벨저울 이미 판매 → NETS 상위모델로 제안 | O34: https://sthpanama.com/contacto/
A35: 34 | B35: B | C35: 파나마 | D35: Grupo Único Internacional (CPG Panamá) | E35: Panama City | F35: cpgpanama.com | G35: ventas@cpgpanama.com; cpg507@outlook.com | H35: +507 217-1328; +507 6371-0258 | I35: cpgpanama.com/contactanos/ | J35: 주력은 라벨·롤지 – 저울 판매 근거 약함 | K35: 저울용 감열라벨, 영수증롤, 바코드, 저울 | L35: 유통(소모품) | M35: 중 | N35: 저울 라벨 판매 중 → 하드웨어+소모품 패키지 적합 | O35: https://www.cpgpanama.com/categoria-producto/etiquetas/etiquetas-termica-para-balanzas/
A36: 35 | B36: B | C36: 파나마 | D36: Posper Panamá | E36: Panama City | F36: posperpanama.com | G36: ventas@posperpanama.com; ventas2@posperpanama.com | I36: posperpanama.com/contactenos/ | J36: WA +507 6154-5057; +507 382-3700 | K36: 슈퍼마켓 POS, Datalogic 스캐너저울, 저울 교정 | L36: POS 딜러 | M36: 중상 | N36: 슈퍼마켓 POS 채널 | O36: https://posperpanama.com/soluciones-para-comercio-minorista-retail/
A37: 36 | B37: C | C37: 파나마 | D37: Industrial Scales of Panama, S.A. | E37: Panama City | G37: balanzas@cableonda.net | H37: 223-2231 | I37: 기존 조사 (회사 사이트/디렉토리) | K37: 저울 수리·교정 | L37: 서비스 | M37: 중하 | N37: 서비스/교정 파트너 | O37: https://sites.google.com/metrologiaindustrial.com/laboratoriometrologia/contactenos
A38: 37 | B38: C | C38: 파나마 | D38: CAS Latinoamérica S.A.S. (파나마) | E38: Panama City | F38: caslatinoamerica.com | G38: panama@caslatinoamerica.com | H38: +507 260-0114 | I38: 기존 조사 (회사 사이트/디렉토리) | K38: CAS 라벨저울 전 라인 | L38: CAS 유통 | M38: 하 | N38: 직접 경쟁사 채널 – 시장정보용 | O38: https://www.caslatinoamerica.com/
A39: 38 | B39: A | C39: 콜롬비아 | D39: BBG Colombia SAS (Básculas y Balanzas Guadalupe) | E39: Medellín 본사 + Bogotá, Cali, Barranquilla, Bucaramanga | F39: bbg.com.co | G39: ventas@basculasbbg.com; distribuidoresmedellin@basculasbbg.com; medellin@basculasbbg.com; info@basculasbbg.com | H39: (604) 557 8785; 311 214 2629; 316 655 0853 | I39: bbg.com.co/basculas/sp/contactenos | J39: 전국 PBX 601 745 7700; WA 317 705 1120 | K39: CAS 라벨저울(CL5200 등), Torrey, 정육장비 – 수입·제조·유통 | L39: 수입/유통(다지점) | M39: 상 | N39: 전국 멀티브랜드 대형 수입사, 라벨저울 판매 중, 딜러가격 운영 | O39: https://www.bbg.com.co/basculas/vp490/sp/balanza-etiquetadora-liquidadora-cas-cl-5200-p
A40: 39 | B40: B | C40: 콜롬비아 | D40: Capital Colombia | E40: Bogotá | F40: capitalcolombia.com | H40: (+57) 601 537 3270; 300 617 1853 | J40: 이메일 미공개 – WA 300 617 1853, 문의폼 capitalcolombia.com/sec-contactenos (주력은 라벨프린터·태블릿) | K40: POS HW: POS저울, 프린터저울, 가격표시기, 라벨프린터(CAS 등) | L40: POS 유통 | M40: 중 | N40: 소매·슈퍼 POS 채널, POS와 저울 번들 | O40: https://www.capitalcolombia.com/clases/colombia/bogota/hardware/balanzas_para_puntos_de_venta_balanzas_con_impresora_y_visores_de_precios_cc19c.php?marcaid=63
...

Sheet 국가별 진입 노트
A1: 국가 | B1: 인증/규제 (법정계량) | C1: 주요 경쟁 브랜드 | D1: 비고/불확실성
A2: 멕시코 | B2: NOM-010-SCFI-1994 + DGN 모델승인 등록, PROFECO 초기·정기 검정(홀로그램) | C2: Torrey(현지), Rhino, DIGI(Mexba), CAS(바하 지역 POS딜러), Bizerba/Dibal/Mettler(체인) | D2: NOM-EM-020-SE-2020 적용 여부 미확인
A3: 과테말라 | B3: DIACO·CENAME 점검 / 소매저울 형식승인 규정 미확인 → OIML R76 + 현지 교정이 실무 요건으로 추정 | C3: CAS(엘살바도르 독점사 경유), Torrey | D3: 불확실
A4: 엘살바도르 | B4: 소비자보호청 점검 시 연 1회 공인업체 교정증명서·스티커 필요 | C4: CAS(중미 북부 독점), Rhino/Vinson/Torrey
A5: 온두라스 | B5: SDE 소비자보호국(Decree 24-2008) 정확도 점검, 형식승인 제도 미확인 | C5: Torrey, CAS, Rice Lake(산업) | D5: 2019년 자료
A6: 니카라과 | B6: 규정 미조사 – 현지 수입사·MIFIC 확인 필요 | C6: CAS, Kretz, Ishida, Rice Lake
A7: 코스타리카 | B7: LACOMET(MEIC) 법정계량 점검, RTCR 존재 여부 미확인 | C7: Dibal 압도적, CAS(Reproma)
A8: 파나마 | B8: ACODECO 점검, DGNTI-COPANIT 37-2002 (현행 여부 확인), POS는 DGI 전자세금계산서 필요 | C8: CAS 직영 사무소, Aclas·Kretz(POS딜러), Datalogic
A9: 콜롬비아 | B9: SIC 비자동저울 기술규정(Res. 33187/2023) – OIML 형식시험 인증서 + 적합성 선언 + SIMEL 등록 필수 | C9: CAS 매우 강함, Dibal 2위, DIGI·Mettler(대형체인) | D9: 2026년 개정안 공포 여부 미확인
A10: 에콰도르 | B10: INEN 기술규정/INEN-1 인증(VUE/Ecuapass) – 저울 해당 RTE 번호 확인 필요. 달러 경제(환리스크 낮음) | C10: CAS 지배적(위조품 유통), DIGI, Mettler
A11: 도미니카공화국 | B11: INDOCAL 법정계량(콜마도 연1회 점검), Pro Consumidor 합동점검. 모델승인 인증 존재 추정 – 확인 | C11: CAS(Balanzas Industriales), Mettler | D11: 주요 체인: Sirena, Nacional, Jumbo, Bravo
A12: 베네수엘라 | B12: SENCAMER 현지 인증 필요(외국 인증 불인정 보고). 외환통제·제재 심사 – 선금/확인 L/C 권장 | C12: CAS 독점대리, Xacta(현지제조) | D12: 결제 리스크 높음
A13: 푸에르토리코 | B13: 미국 영토 – NTEP 인증(NIST HB44) 필수, DACO 검사, FCC·UL/ETL 필요 | C13: CAS 독점(SBM), Hobart, Mettler, Bizerba, DIGI | D13: NTEP 없으면 판매 불가
A14: 쿠바 | B14: 국영기업/Mipymes 경유, 장기 외상·미수 위험, 미국 금수조치로 USD 결제 곤란 | C14: - | D14: 파나마/스페인 무역상 경유만 현실적, 리드 미조사
A15: 페루 | B15: INACAL R.D. 006-2018: 100kg 이하 상거래 저울 모델승인+초기/정기 검정(NMP 003:2009=OIML R76). 외국 승인서 인정 가능 → OIML R76 인증서 매우 유리. 한-페루 FTA(2011) | C15: CAS(Gufra, Miyake), DIGI/Teraoka, Mettler | D15: HS 8423.81 무관세 여부 확인 필요
A16: 칠레 | B16: 상거래 저울 의무 형식승인 불명확, 어댑터 SEC 전기안전 인증 가능성 – INN/SEC 확인. 한-칠레 FTA(2004) 대부분 무관세 | C16: Dibal, DIGI, Mettler, Systel – CAS 채널 미확인 = 한국 브랜드 기회
A17: 볼리비아 | B17: DS 5103(2024) + RM 044/2024: 통관 시 IBMETRO 증명서(CRTM 모델승인, CCRT 적합성) 필수 – 첫 선적 전 준비. FTA 없음 | C17: CAS, Toledo do Brasil, Mettler, Systel | D17: 시장 작음, 최대 체인 Hipermaxi
A18: 아르헨티나 | B18: Ley 19.511: 현지 수입사가 INTI 시험 → 상무부 모델승인 + 최초검정, RUMP 등록 (balanzas@inti.gob.ar). 메르코수르 공동관세, 수입·외환 규정 수시 변경 | C18: Systel·Kretz(현지) 지배적, DIGI(Hasar), Bizerba, Mettler | D18: 통관사(despachante) 확인 필요
A19: 우루과이 | B19: LATU 법정계량 승인·관리 필수, 메르코수르 공동관세 | C19: Dibal(Baudin), Systel, Kretz(Ser-Tec), Mettler | D19: 주요 체인: Disco/Devoto/Géant, Tienda Inglesa
A20: 파라과이 | B20: INTN-ONM 정기검정 봉인(연 1회) 필수, 수입 모델승인 여부 미확인 | C20: Kretz, Systel, DINA(Balpar), Dibal | D20: Balpar가 사실상 관문
A21: 적도기니 | B21: CEMAC 회원국, 법정계량 제도 불명확, 현지 유통사 미발견 | C21: - | D21: 스페인 딜러 또는 카메룬/가봉 유통사 경유 – 우선순위 최하
A23: 공통 TIP
A24: • | B24: OIML R76 인증서(가능하면 MID/OIML MAA)를 확보하면 페루·콜롬비아·볼리비아 등 형식승인이 크게 쉬워짐
A25: • | B25: CAS(한국 경쟁사)가 중남미 전역에 깔려 있음 → 'CAS 대비 가격/기능/라벨 소프트웨어 우위' 비교표를 준비
A26: • | B26: 스페인어 카탈로그·라벨 SW UI·매뉴얼 필수, 저울 라벨 소모품 공급 조건도 함께 제안
A27: • | B27: 결제: 베네수엘라·쿠바·아르헨티나는 선금 또는 확인 L/C
